Workbook

Sheet Assumptions
A1: Location | B1: Price P0 | C1: Qty Q0 | D1: Elasticity (neg) | G1: inelastic emand | H1: Elasctic
A2: Polin - Shelter | B2: 45 | C2: 9 | D2: -0.5 | G2: e<1 | H2: e>1
A3: A. Ramsey - Shelter | B3: 85 | C3: 44 | D3: -0.5
A4: Arsenal - Shelter | B4: 85 | C4: 28 | D4: -0.5
A5: Babe Denny -Shelter | B5: 0 | C5: 2 | D5: -0.5
A6: Bel Aire - Shelter #1 | B6: 85 | C6: 33 | D6: -0.5
A7: Bel Aire - Shelter #2/Pavilion | B7: 85 | C7: 2 | D7: -0.5
A8: Bellamy - Shelter 1 | B8: 85 | C8: 1 | D8: -0.5
A9: Bertha Ross - Shelter #1 (Top of Hill) | B9: 85 | C9: 9 | D9: -0.5
A10: Bertha Ross - Shelter #2 (Bottom) | B10: 110 | C10: 22 | D10: -0.5
A11: BR - Lawn Space | B11: 20 | C11: 26 | D11: -0.5
A12: BR - Picnic Knoll | B12: 70 | C12: 67 | D12: -0.5
A13: BR - Shelter #1 | B13: 285 | C13: 97 | D13: -0.5
A14: BR - Shelter #2 | B14: 135 | C14: 103 | D14: -0.5
... A114: WISH - Shelter | B114: 85 | C114: 8 | D114: -0.5

Sheet Elasticty Model
A1: Location | B1: Baseline Price P0 | C1: Baseline Qty Q0 | D1: Elasticity (neg) | E1: b (slope) = -E*Q0/P0 | F1: a (intercept) = Q0 + b*P0 | G1: Proposed Price P1 (type) | H1: Projected Qty Q1 | I1: old Revenue | J1: Proposed Revenue | K1: ΔRevenue % = Rev1/Rev0 - 1 | L1: Elasticity at P1 = -b*P1/Q1 | M1: Elasticity | O1: Max demand when price=0 | P1: projected quanity at max p | Q1: profit max price | R1: proposed max profit | S1: marignal rev | T1: Demand function= | V1: a+ | W1: b | X1: p0
A2: =Assumptions!A2 -> Polin - Shelter | B2: =Assumptions!B2 -> 45 | C2: =Assumptions!C2 -> 9 | D2: =Assumptions!D2 -> -0.5 | E2: =-1*D2*C2/B2 -> 0.1 | F2: =C2+E2*B2 -> 13.5 | G2: 60 | H2: =F2-E2*G2 -> 7.5 | I2: =B2*C2 -> 405 | J2: =G2*H2 -> 450 | K2: =J2/I2-1 -> 0.11111111 | L2: =-1*E2*G2/H2 -> -0.8 | M2: =Assumptions!D2 -> -0.5 | O2: =F2-E2*0 -> 13.5 | P2: =F2-E2*Q2 -> 6.75 | Q2: =V2/(W2*2) -> 67.5 | R2: =P2*Q2 -> 455.625 | S2: =(Table3[[#This Row],[Proposed Revenue]]-I2)/(H2-C2) -> -30 | T2: Qd = a - bP | V2: =C2+W2*(B2) -> 13.5 | W2: =ABS(M2)*(C2/B2) -> 0.1 | X2: =B2 -> 45
A3: =Assumptions!A3 -> A. Ramsey - Shelter | B3: =Assumptions!B3 -> 85 | C3: =Assumptions!C3 -> 44 | D3: =Assumptions!D3 -> -0.5 | E3: =-1*D3*C3/B3 -> 0.25882353 | F3: =C3+E3*B3 -> 66 | G3: 100 | H3: =F3-E3*G3 -> 40.117647 | I3: =B3*C3 -> 3740 | J3: =G3*H3 -> 4011.7647 | K3: =J3/I3-1 -> 0.07266436 | L3: =-1*E3*G3/H3 -> -0.64516129 | M3: =Assumptions!D3 -> -0.5 | O3: =F3-E3*0 -> 66 | P3: =F3-E3*Q3 -> 33 | Q3: =V3/(W3*2) -> 127.5 | R3: =P3*Q3 -> 4207.5 | S3: =(Table3[[#This Row],[Proposed Revenue]]-I3)/(H3-C3) -> -70 | V3: =C3+W3*(B3) -> 66 | W3: =ABS(M3)*(C3/B3) -> 0.25882353 | X3: =B3 -> 85
A4: =Assumptions!A4 -> Arsenal - Shelter | B4: =Assumptions!B4 -> 85 | C4: =Assumptions!C4 -> 28 | D4: =Assumptions!D4 -> -0.5 | E4: =-1*D4*C4/B4 -> 0.16470588 | F4: =C4+E4*B4 -> 42 | G4: 100 | H4: =F4-E4*G4 -> 25.529412 | I4: =B4*C4 -> 2380 | J4: =G4*H4 -> 2552.9412 | K4: =J4/I4-1 -> 0.07266436 | L4: =-1*E4*G4/H4 -> -0.64516129 | M4: =Assumptions!D4 -> -0.5 | O4: =F4-E4*0 -> 42 | P4: =F4-E4*Q4 -> 21 | Q4: =V4/(W4*2) -> 127.5 | R4: =P4*Q4 -> 2677.5 | S4: =(Table3[[#This Row],[Proposed Revenue]]-I4)/(H4-C4) -> -70 | V4: =C4+W4*(B4) -> 42 | W4: =ABS(M4)*(C4/B4) -> 0.16470588 | X4: =B4 -> 85
A5: =Assumptions!A5 -> Babe Denny -Shelter | B5: =Assumptions!B5 -> 0 | C5: =Assumptions!C5 -> 2 | D5: =Assumptions!D5 -> -0.5 | E5: =-1*D5*C5/B5 -> #DIV/0! | F5: =C5+E5*B5 -> #DIV/0! | G5: 15 | H5: =F5-E5*G5 -> #DIV/0! | I5: =B5*C5 -> 0 | J5: =G5*H5 -> #DIV/0! | K5: =J5/I5-1 -> #DIV/0! | L5: =-1*E5*G5/H5 -> #DIV/0! | M5: =Assumptions!D5 -> -0.5 | O5: =F5-E5*0 -> #DIV/0! | P5: =F5-E5*Q5 -> #DIV/0! | Q5: =V5/(W5*2) -> #DIV/0! | R5: =P5*Q5 -> #DIV/0! | S5: =(Table3[[#This Row],[Proposed Revenue]]-I5)/(H5-C5) -> #DIV/0! | V5: =C5+W5*(B5) -> #DIV/0! | W5: =ABS(M5)*(C5/B5) -> #DIV/0! | X5: =B5 -> 0
A6: =Assumptions!A6 -> Bel Aire - Shelter #1 | B6: =Assumptions!B6 -> 85 | C6: =Assumptions!C6 -> 33 | D6: =Assumptions!D6 -> -0.5 | E6: =-1*D6*C6/B6 -> 0.19411765 | F6: =C6+E6*B6 -> 49.5 | G6: 100 | H6: =F6-E6*G6 -> 30.088235 | I6: =B6*C6 -> 2805 | J6: =G6*H6 -> 3008.8235 | K6: =J6/I6-1 -> 0.07266436 | L6: =-1*E6*G6/H6 -> -0.64516129 | M6: =Assumptions!D6 -> -0.5 | O6: =F6-E6*0 -> 49.5 | P6: =F6-E6*Q6 -> 24.75 | Q6: =V6/(W6*2) -> 127.5 | R6: =P6*Q6 -> 3155.625 | S6: =(Table3[[#This Row],[Proposed Revenue]]-I6)/(H6-C6) -> -70 | V6: =C6+W6*(B6) -> 49.5 | W6: =ABS(M6)*(C6/B6) -> 0.19411765 | X6: =B6 -> 85
A7: =Assumptions!A7 -> Bel Aire - Shelter #2/Pavilion | B7: =Assumptions!B7 -> 85 | C7: =Assumptions!C7 -> 2 | D7: =Assumptions!D7 -> -0.5 | E7: =-1*D7*C7/B7 -> 0.011764706 | F7: =C7+E7*B7 -> 3 | G7: 100 | H7: =F7-E7*G7 -> 1.8235294 | I7: =B7*C7 -> 170 | J7: =G7*H7 -> 182.35294 | K7: =J7/I7-1 -> 0.07266436 | L7: =-1*E7*G7/H7 -> -0.64516129 | M7: =Assumptions!D7 -> -0.5 | O7: =F7-E7*0 -> 3 | P7: =F7-E7*Q7 -> 1.5 | Q7: =V7/(W7*2) -> 127.5 | R7: =P7*Q7 -> 191.25 | S7: =(Table3[[#This Row],[Proposed Revenue]]-I7)/(H7-C7) -> -70 | V7: =C7+W7*(B7) -> 3 | W7: =ABS(M7)*(C7/B7) -> 0.011764706 | X7: =B7 -> 85
A8: =Assumptions!A8 -> Bellamy - Shelter 1 | B8: =Assumptions!B8 -> 85 | C8: =Assumptions!C8 -> 1 | D8: =Assumptions!D8 -> -0.5 | E8: =-1*D8*C8/B8 -> 0.0058823529 | F8: =C8+E8*B8 -> 1.5 | G8: 100 | H8: =F8-E8*G8 -> 0.91176471 | I8: =B8*C8 -> 85 | J8: =G8*H8 -> 91.176471 | K8: =J8/I8-1 -> 0.07266436 | L8: =-1*E8*G8/H8 -> -0.64516129 | M8: =Assumptions!D8 -> -0.5 | O8: =F8-E8*0 -> 1.5 | P8: =F8-E8*Q8 -> 0.75 | Q8: =V8/(W8*2) -> 127.5 | R8: =P8*Q8 -> 95.625 | S8: =(Table3[[#This Row],[Proposed Revenue]]-I8)/(H8-C8) -> -70 | V8: =C8+W8*(B8) -> 1.5 | W8: =ABS(M8)*(C8/B8) -> 0.0058823529 | X8: =B8 -> 85
A9: =Assumptions!A9 -> Bertha Ross - Shelter #1 (Top of Hill) | B9: =Assumptions!B9 -> 85 | C9: =Assumptions!C9 -> 9 | D9: =Assumptions!D9 -> -0.5 | E9: =-1*D9*C9/B9 -> 0.052941176 | F9: =C9+E9*B9 -> 13.5 | G9: 100 | H9: =F9-E9*G9 -> 8.2058824 | I9: =B9*C9 -> 765 | J9: =G9*H9 -> 820.58824 | K9: =J9/I9-1 -> 0.07266436 | L9: =-1*E9*G9/H9 -> -0.64516129 | M9: =Assumptions!D9 -> -0.5 | O9: =F9-E9*0 -> 13.5 | P9: =F9-E9*Q9 -> 6.75 | Q9: =V9/(W9*2) -> 127.5 | R9: =P9*Q9 -> 860.625 | S9: =(Table3[[#This Row],[Proposed Revenue]]-I9)/(H9-C9) -> -70 | V9: =C9+W9*(B9) -> 13.5 | W9: =ABS(M9)*(C9/B9) -> 0.052941176 | X9: =B9 -> 85
A10: =Assumptions!A10 -> Bertha Ross - Shelter #2 (Bottom) | B10: =Assumptions!B10 -> 110 | C10: =Assumptions!C10 -> 22 | D10: =Assumptions!D10 -> -0.5 | E10: =-1*D10*C10/B10 -> 0.1 | F10: =C10+E10*B10 -> 33 | G10: 125 | H10: =F10-E10*G10 -> 20.5 | I10: =B10*C10 -> 2420 | J10: =G10*H10 -> 2562.5 | K10: =J10/I10-1 -> 0.058884298 | L10: =-1*E10*G10/H10 -> -0.6097561 | M10: =Assumptions!D10 -> -0.5 | O10: =F10-E10*0 -> 33 | P10: =F10-E10*Q10 -> 16.5 | Q10: =V10/(W10*2) -> 165 | R10: =P10*Q10 -> 2722.5 | S10: =(Table3[[#This Row],[Proposed Revenue]]-I10)/(H10-C10) -> -95 | V10: =C10+W10*(B10) -> 33 | W10: =ABS(M10)*(C10/B10) -> 0.1 | X10: =B10 -> 110
A11: =Assumptions!A11 -> BR - Lawn Space | B11: =Assumptions!B11 -> 20 | C11: =Assumptions!C11 -> 26 | D11: =Assumptions!D11 -> -0.5 | E11: =-1*D11*C11/B11 -> 0.65 | F11: =C11+E11*B11 -> 39 | G11: 35 | H11: =F11-E11*G11 -> 16.25 | I11: =B11*C11 -> 520 | J11: =G11*H11 -> 568.75 | K11: =J11/I11-1 -> 0.09375 | L11: =-1*E11*G11/H11 -> -1.4 | M11: =Assumptions!D11 -> -0.5 | O11: =F11-E11*0 -> 39 | P11: =F11-E11*Q11 -> 19.5 | Q11: =V11/(W11*2) -> 30 | R11: =P11*Q11 -> 585 | S11: =(Table3[[#This Row],[Proposed Revenue]]-I11)/(H11-C11) -> -5 | V11: =C11+W11*(B11) -> 39 | W11: =ABS(M11)*(C11/B11) -> 0.65 | X11: =B11 -> 20
A12: =Assumptions!A12 -> BR - Picnic Knoll | B12: =Assumptions!B12 -> 70 | C12: =Assumptions!C12 -> 67 | D12: =Assumptions!D12 -> -0.5 | E12: =-1*D12*C12/B12 -> 0.47857143 | F12: =C12+E12*B12 -> 100.5 | G12: 85 | H12: =F12-E12*G12 -> 59.821429 | I12: =B12*C12 -> 4690 | J12: =G12*H12 -> 5084.8214 | K12: =J12/I12-1 -> 0.084183673 | L12: =-1*E12*G12/H12 -> -0.68 | M12: =Assumptions!D12 -> -0.5 | O12: =F12-E12*0 -> 100.5 | P12: =F12-E12*Q12 -> 50.25 | Q12: =V12/(W12*2) -> 105 | R12: =P12*Q12 -> 5276.25 | S12: =(Table3[[#This Row],[Proposed Revenue]]-I12)/(H12-C12) -> -55 | V12: =C12+W12*(B12) -> 100.5 | W12: =ABS(M12)*(C12/B12) -> 0.47857143 | X12: =B12 -> 70
A13: =Assumptions!A13 -> BR - Shelter #1 | B13: =Assumptions!B13 -> 285 | C13: =Assumptions!C13 -> 97 | D13: =Assumptions!D13 -> -0.5 | E13: =-1*D13*C13/B13 -> 0.17017544 | F13: =C13+E13*B13 -> 145.5 | G13: 300 | H13: =F13-E13*G13 -> 94.447368 | I13: =B13*C13 -> 27645 | J13: =G13*H13 -> 28334.211 | K13: =J13/I13-1 -> 0.024930748 | L13: =-1*E13*G13/H13 -> -0.54054054 | M13: =Assumptions!D13 -> -0.5 | O13: =F13-E13*0 -> 145.5 | P13: =F13-E13*Q13 -> 72.75 | Q13: =V13/(W13*2) -> 427.5 | R13: =P13*Q13 -> 31100.625 | S13: =(Table3[[#This Row],[Proposed Revenue]]-I13)/(H13-C13) -> -270 | V13: =C13+W13*(B13) -> 145.5 | W13: =ABS(M13)*(C13/B13) -> 0.17017544 | X13: =B13 -> 285
A14: =Assumptions!A14 -> BR - Shelter #2 | B14: =Assumptions!B14 -> 135 | C14: =Assumptions!C14 -> 103 | D14: =Assumptions!D14 -> -0.5 | E14: =-1*D14*C14/B14 -> 0.38148148 | F14: =C14+E14*B14 -> 154.5 | G14: 150 | H14: =F14-E14*G14 -> 97.277778 | I14: =B14*C14 -> 13905 | J14: =G14*H14 -> 14591.667 | K14: =J14/I14-1 -> 0.049382716 | L14: =-1*E14*G14/H14 -> -0.58823529 | M14: =Assumptions!D14 -> -0.5 | O14: =F14-E14*0 -> 154.5 | P14: =F14-E14*Q14 -> 77.25 | Q14: =V14/(W14*2) -> 202.5 | R14: =P14*Q14 -> 15643.125 | S14: =(Table3[[#This Row],[Proposed Revenue]]-I14)/(H14-C14) -> -120 | V14: =C14+W14*(B14) -> 154.5 | W14: =ABS(M14)*(C14/B14) -> 0.38148148 | X14: =B14 -> 135
... A101: =Assumptions!A101 -> Spades - Pagoda | B101: =Assumptions!B101 -> 0 | C101: =Assumptions!C101 -> 1 | D101: =Assumptions!D101 -> -0.5 | E101: =-1*D101*C101/B101 -> #DIV/0! | F101: =C101+E101*B101 -> #DIV/0! | G101: 15 | H101: =F101-E101*G101 -> #DIV/0! | I101: =B101*C101 -> 0 | J101: =G101*H101 -> #DIV/0! | K101: =J101/I101-1 -> #DIV/0! | L101: =-1*E101*G101/H101 -> #DIV/0! | M101: =Assumptions!D101 -> -0.5 | O101: =F101-E101*0 -> #DIV/0! | P101: =F101-E101*Q101 -> #DIV/0! | Q101: =V101/(W101*2) -> #DIV/0! | R101: =P101*Q101 -> #DIV/0! | S101: =(Table3[[#This Row],[Proposed Revenue]]-I101)/(H101-C101) -> #DIV/0! | V101: =C101+W101*(B101) -> #DIV/0! | W101: =ABS(M101)*(C101/B101) -> #DIV/0! | X101: =B101 -> 0
A102: =Assumptions!A102 -> Stanley Strader (Bethel) - Shelter #1 | B102: =Assumptions!B102 -> 110 | C102: =Assumptions!C102 -> 10 | D102: =Assumptions!D102 -> -0.5 | E102: =-1*D102*C102/B102 -> 0.045454545 | F102: =C102+E102*B102 -> 15 | G102: 125 | H102: =F102-E102*G102 -> 9.3181818 | I102: =B102*C102 -> 1100 | J102: =G102*H102 -> 1164.7727 | M102: =Assumptions!D102 -> -0.5 | O102: =F102-E102*0 -> 15 | P102: =F102-E102*Q102 -> 7.5 | Q102: =V102/(W102*2) -> 165 | R102: =P102*Q102 -> 1237.5 | S102: =(Table3[[#This Row],[Proposed Revenue]]-I102)/(H102-C102) -> -95 | V102: =C102+W102*(B102) -> 15 | W102: =ABS(M102)*(C102/B102) -> 0.045454545 | X102: =B102 -> 110
A103: =Assumptions!A103 -> Stout - Shelter | B103: =Assumptions!B103 -> 45 | C103: =Assumptions!C103 -> 12 | D103: =Assumptions!D103 -> -0.5 | E103: =-1*D103*C103/B103 -> 0.13333333 | F103: =C103+E103*B103 -> 18 | G103: 60 | H103: =F103-E103*G103 -> 10 | I103: =B103*C103 -> 540 | J103: =G103*H103 -> 600 | M103: =Assumptions!D103 -> -0.5 | O103: =F103-E103*0 -> 18 | P103: =F103-E103*Q103 -> 9 | Q103: =V103/(W103*2) -> 67.5 | R103: =P103*Q103 -> 607.5 | S103: =(Table3[[#This Row],[Proposed Revenue]]-I103)/(H103-C103) -> -30 | V103: =C103+W103*(B103) -> 18 | W103: =ABS(M103)*(C103/B103) -> 0.13333333 | X103: =B103 -> 45
A104: =Assumptions!A104 -> Thatcher - Shelter #1 | B104: =Assumptions!B104 -> 85 | C104: =Assumptions!C104 -> 23 | D104: =Assumptions!D104 -> -0.5 | E104: =-1*D104*C104/B104 -> 0.13529412 | F104: =C104+E104*B104 -> 34.5 | G104: 100 | H104: =F104-E104*G104 -> 20.970588 | I104: =B104*C104 -> 1955 | J104: =G104*H104 -> 2097.0588 | M104: =Assumptions!D104 -> -0.5 | O104: =F104-E104*0 -> 34.5 | P104: =F104-E104*Q104 -> 17.25 | Q104: =V104/(W104*2) -> 127.5 | R104: =P104*Q104 -> 2199.375 | S104: =(Table3[[#This Row],[Proposed Revenue]]-I104)/(H104-C104) -> -70 | V104: =C104+W104*(B104) -> 34.5 | W104: =ABS(M104)*(C104/B104) -> 0.13529412 | X104: =B104 -> 85
A105: =Assumptions!A105 -> Thatcher - Shelter #2 | B105: =Assumptions!B105 -> 75 | C105: =Assumptions!C105 -> 18 | D105: =Assumptions!D105 -> -0.5 | E105: =-1*D105*C105/B105 -> 0.12 | F105: =C105+E105*B105 -> 27 | G105: 90 | H105: =F105-E105*G105 -> 16.2 | I105: =B105*C105 -> 1350 | J105: =G105*H105 -> 1458 | M105: =Assumptions!D105 -> -0.5 | O105: =F105-E105*0 -> 27 | P105: =F105-E105*Q105 -> 13.5 | Q105: =V105/(W105*2) -> 112.5 | R105: =P105*Q105 -> 1518.75 | S105: =(Table3[[#This Row],[Proposed Revenue]]-I105)/(H105-C105) -> -60 | V105: =C105+W105*(B105) -> 27 | W105: =ABS(M105)*(C105/B105) -> 0.12 | X105: =B105 -> 75
A106: =Assumptions!A106 -> Thompson - Shelter | B106: =Assumptions!B106 -> 100 | C106: =Assumptions!C106 -> 9 | D106: =Assumptions!D106 -> -0.5 | E106: =-1*D106*C106/B106 -> 0.045 | F106: =C106+E106*B106 -> 13.5 | G106: 115 | H106: =F106-E106*G106 -> 8.325 | I106: =B106*C106 -> 900 | J106: =G106*H106 -> 957.375 | M106: =Assumptions!D106 -> -0.5 | O106: =F106-E106*0 -> 13.5 | P106: =F106-E106*Q106 -> 6.75 | Q106: =V106/(W106*2) -> 150 | R106: =P106*Q106 -> 1012.5 | S106: =(Table3[[#This Row],[Proposed Revenue]]-I106)/(H106-C106) -> -85 | V106: =C106+W106*(B106) -> 13.5 | W106: =ABS(M106)*(C106/B106) -> 0.045 | X106: =B106 -> 100
A107: =Assumptions!A107 -> Washington Park - Shelter #1 | B107: =Assumptions!B107 -> 110 | C107: =Assumptions!C107 -> 13 | D107: =Assumptions!D107 -> -0.5 | E107: =-1*D107*C107/B107 -> 0.059090909 | F107: =C107+E107*B107 -> 19.5 | G107: 125 | H107: =F107-E107*G107 -> 12.113636 | I107: =B107*C107 -> 1430 | J107: =G107*H107 -> 1514.2045 | M107: =Assumptions!D107 -> -0.5 | O107: =F107-E107*0 -> 19.5 | P107: =F107-E107*Q107 -> 9.75 | Q107: =V107/(W107*2) -> 165 | R107: =P107*Q107 -> 1608.75 | S107: =(Table3[[#This Row],[Proposed Revenue]]-I107)/(H107-C107) -> -95 | V107: =C107+W107*(B107) -> 19.5 | W107: =ABS(M107)*(C107/B107) -> 0.059090909 | X107: =B107 -> 110
A108: =Assumptions!A108 -> Washington Park - Shelter #2 | B108: =Assumptions!B108 -> 110 | C108: =Assumptions!C108 -> 5 | D108: =Assumptions!D108 -> -0.5 | E108: =-1*D108*C108/B108 -> 0.022727273 | F108: =C108+E108*B108 -> 7.5 | G108: 125 | H108: =F108-E108*G108 -> 4.6590909 | I108: =B108*C108 -> 550 | J108: =G108*H108 -> 582.38636 | M108: =Assumptions!D108 -> -0.5 | O108: =F108-E108*0 -> 7.5 | P108: =F108-E108*Q108 -> 3.75 | Q108: =V108/(W108*2) -> 165 | R108: =P108*Q108 -> 618.75 | S108: =(Table3[[#This Row],[Proposed Revenue]]-I108)/(H108-C108) -> -95 | V108: =C108+W108*(B108) -> 7.5 | W108: =ABS(M108)*(C108/B108) -> 0.022727273 | X108: =B108 -> 110
A109: =Assumptions!A109 -> Watkins - Shelter #1 | B109: =Assumptions!B109 -> 110 | C109: =Assumptions!C109 -> 8 | D109: =Assumptions!D109 -> -0.5 | E109: =-1*D109*C109/B109 -> 0.036363636 | F109: =C109+E109*B109 -> 12 | G109: 125 | H109: =F109-E109*G109 -> 7.4545455 | I109: =B109*C109 -> 880 | J109: =G109*H109 -> 931.81818 | M109: =Assumptions!D109 -> -0.5 | O109: =F109-E109*0 -> 12 | P109: =F109-E109*Q109 -> 6 | Q109: =V109/(W109*2) -> 165 | R109: =P109*Q109 -> 990 | S109: =(Table3[[#This Row],[Proposed Revenue]]-I109)/(H109-C109) -> -95 | V109: =C109+W109*(B109) -> 12 | W109: =ABS(M109)*(C109/B109) -> 0.036363636 | X109: =B109 -> 110
A110: =Assumptions!A110 -> Wes Montgomery - Shelter 1 | B110: =Assumptions!B110 -> 110 | C110: =Assumptions!C110 -> 11 | D110: =Assumptions!D110 -> -0.5 | E110: =-1*D110*C110/B110 -> 0.05 | F110: =C110+E110*B110 -> 16.5 | G110: 125 | H110: =F110-E110*G110 -> 10.25 | I110: =B110*C110 -> 1210 | J110: =G110*H110 -> 1281.25 | M110: =Assumptions!D110 -> -0.5 | O110: =F110-E110*0 -> 16.5 | P110: =F110-E110*Q110 -> 8.25 | Q110: =V110/(W110*2) -> 165 | R110: =P110*Q110 -> 1361.25 | S110: =(Table3[[#This Row],[Proposed Revenue]]-I110)/(H110-C110) -> -95 | V110: =C110+W110*(B110) -> 16.5 | W110: =ABS(M110)*(C110/B110) -> 0.05 | X110: =B110 -> 110
A111: =Assumptions!A111 -> Wes Montgomery - Shelter 2 | B111: =Assumptions!B111 -> 85 | C111: =Assumptions!C111 -> 8 | D111: =Assumptions!D111 -> -0.5 | E111: =-1*D111*C111/B111 -> 0.047058824 | F111: =C111+E111*B111 -> 12 | G111: 100 | H111: =F111-E111*G111 -> 7.2941176 | I111: =B111*C111 -> 680 | J111: =G111*H111 -> 729.41176 | M111: =Assumptions!D111 -> -0.5 | O111: =F111-E111*0 -> 12 | P111: =F111-E111*Q111 -> 6 | Q111: =V111/(W111*2) -> 127.5 | R111: =P111*Q111 -> 765 | S111: =(Table3[[#This Row],[Proposed Revenue]]-I111)/(H111-C111) -> -70 | V111: =C111+W111*(B111) -> 12 | W111: =ABS(M111)*(C111/B111) -> 0.047058824 | X111: =B111 -> 85
A112: =Assumptions!A112 -> Wildwood - Shelter 1 | B112: =Assumptions!B112 -> 85 | C112: =Assumptions!C112 -> 24 | D112: =Assumptions!D112 -> -0.5 | E112: =-1*D112*C112/B112 -> 0.14117647 | F112: =C112+E112*B112 -> 36 | G112: 100 | H112: =F112-E112*G112 -> 21.882353 | I112: =B112*C112 -> 2040 | J112: =G112*H112 -> 2188.2353 | M112: =Assumptions!D112 -> -0.5 | O112: =F112-E112*0 -> 36 | P112: =F112-E112*Q112 -> 18 | Q112: =V112/(W112*2) -> 127.5 | R112: =P112*Q112 -> 2295 | S112: =(Table3[[#This Row],[Proposed Revenue]]-I112)/(H112-C112) -> -70 | V112: =C112+W112*(B112) -> 36 | W112: =ABS(M112)*(C112/B112) -> 0.14117647 | X112: =B112 -> 85
A113: =Assumptions!A113 -> Windsor- Shelter | B113: =Assumptions!B113 -> 85 | C113: =Assumptions!C113 -> 5 | D113: =Assumptions!D113 -> -0.5 | E113: =-1*D113*C113/B113 -> 0.029411765 | F113: =C113+E113*B113 -> 7.5 | G113: 100 | H113: =F113-E113*G113 -> 4.5588235 | I113: =B113*C113 -> 425 | J113: =G113*H113 -> 455.88235 | M113: =Assumptions!D113 -> -0.5 | O113: =F113-E113*0 -> 7.5 | P113: =F113-E113*Q113 -> 3.75 | Q113: =V113/(W113*2) -> 127.5 | R113: =P113*Q113 -> 478.125 | S113: =(Table3[[#This Row],[Proposed Revenue]]-I113)/(H113-C113) -> -70 | V113: =C113+W113*(B113) -> 7.5 | W113: =ABS(M113)*(C113/B113) -> 0.029411765 | X113: =B113 -> 85
A114: =Assumptions!A114 -> WISH - Shelter | B114: =Assumptions!B114 -> 85 | C114: =Assumptions!C114 -> 8 | D114: =Assumptions!D114 -> -0.5 | E114: =-1*D114*C114/B114 -> 0.047058824 | F114: =C114+E114*B114 -> 12 | G114: 100 | H114: =F114-E114*G114 -> 7.2941176 | I114: =B114*C114 -> 680 | J114: =G114*H114 -> 729.41176 | M114: =Assumptions!D114 -> -0.5 | O114: =F114-E114*0 -> 12 | P114: =F114-E114*Q114 -> 6 | Q114: =V114/(W114*2) -> 127.5 | R114: =P114*Q114 -> 765 | S114: =(Table3[[#This Row],[Proposed Revenue]]-I114)/(H114-C114) -> -70 | V114: =C114+W114*(B114) -> 12 | W114: =ABS(M114)*(C114/B114) -> 0.047058824 | X114: =B114 -> 85
I116: Propsoed sum= | J116: =SUMIF(Table3[Proposed Revenue], "<>#DIV/0!") -> 494301.84 | Q116: Proposed Max= | R116: =SUMIF(Table9[proposed max profit], "<>#DIV/0!") -> 532203.75
H117: old sum | J117: =SUM(I2:I114) -> 473070

Sheet Price Tester
A3: P0 | B3: 45
A4: Q0 | B4: 9
A5: E | B5: -0.9
A6: R1 | B6: =B4*B3 -> 405
A8: b = -E*Q0/P0 | B8: =-1*B5*B4/B3 -> 0.18
A9: a = Q0 + b*P0 | B9: =B4+B8*B3 -> 17.1
G10: function
A11: Step | B11: Price P | C11: Q | D11: Revenue | G11: q=a+bp
A12: 1 | B12: =B3*0.5 -> 22.5 | C12: =B9-B8*B12 -> 13.05 | D12: =B12*C12 -> 293.625 | G12: q= quantity
A13: 2 | B13: =B3*0.6 -> 27 | C13: =B9-B8*B13 -> 12.24 | D13: =B13*C13 -> 330.48 | G13: p= price
A14: 3 | B14: =B3*0.7 -> 31.5 | C14: =B9-B8*B14 -> 11.43 | D14: =B14*C14 -> 360.045 | G14: a= max q
A15: 4 | B15: =B3*0.8 -> 36 | C15: =B9-B8*B15 -> 10.62 | D15: =B15*C15 -> 382.32 | G15: b= slope
A16: 5 | B16: =B3*0.9 -> 40.5 | C16: =B9-B8*B16 -> 9.81 | D16: =B16*C16 -> 397.305 | G16: p- a/b- q/b
A17: 6 | B17: =B3*1 -> 45 | C17: =B9-B8*B17 -> 9 | D17: =B17*C17 -> 405
A18: 7 | B18: =B3*1.1 -> 49.5 | C18: =B9-B8*B18 -> 8.19 | D18: =B18*C18 -> 405.405
A19: 8 | B19: =B3*1.2 -> 54 | C19: =B9-B8*B19 -> 7.38 | D19: =B19*C19 -> 398.52
A20: 9 | B20: =B3*1.3 -> 58.5 | C20: =B9-B8*B20 -> 6.57 | D20: =B20*C20 -> 384.345
A21: 10 | B21: =B3*1.4 -> 63 | C21: =B9-B8*B21 -> 5.76 | D21: =B21*C21 -> 362.88
A22: 11 | B22: =B3*1.5 -> 67.5 | C22: =B9-B8*B22 -> 4.95 | D22: =B22*C22 -> 334.125
A23: 11 | B23: =B4*1.5 -> 13.5 | C23: =B10-B9*B23 -> -230.85 | D23: =B23*C23 -> -3116.475

Sheet cost recovery 
A1: Rental of Facility Rooms (per hour, unless designated | C1: 2025 Current Fee | D1: Proposed 2026 Fee | E1: Cost of Operations/Staff | F1: Total Cost | H1: Old porfit ratio | I1: Nprofit ratio | J1: old cost ratio | K1: Ncost ratio | M1: Notes
A2: Bel Aire (3 hr min) | M2: 2026 prices were 2025 current price plus $20
A3: Community Rm-Weekday/before 6pm M-Th | C3: 40 | D3: =C3+20 -> 60 | E3: $16.20/hr FA/ No Utility Data | F3: 16.2 | H3: =(C3-F3)/C3 -> 0.595 | I3: =(D3-F3)/D3 -> 0.73 | J3: =C3/F3 -> 2.4691358 | K3: =D3/F3 -> 3.7037037 | M3: The profit ratio represents how much of each dollar of revenue is retained as profit after covering operating costs. so for the fist examle with this new fee increase 73% sould be profits if everything stays constant
A4: Community Rm-after 6 pm Friday/Sat/Sun | C4: 80 | D4: =C4+20 -> 100 | E4: $16.20/hr FA/ No Utility Data | F4: 16.2 | H4: =(C4-F4)/C4 -> 0.7975 | I4: =(D4-F4)/D4 -> 0.838 | J4: =C4/F4 -> 4.9382716 | K4: =D4/F4 -> 6.1728395
A5: Community Rm-after 6 pm M-Th | C5: 55 | D5: =C5+20 -> 75 | E5: $16.20/hr FA/ No Utility Data | F5: 16.2 | H5: =(C5-F5)/C5 -> 0.70545455 | I5: =(D5-F5)/D5 -> 0.784 | J5: =C5/F5 -> 3.3950617 | K5: =D5/F5 -> 4.6296296 | M5: The cost ratio tells you how many dollars you earn per dollar of cost. for example 3.7 means that for every $1 spent on cost with the new fee earn $3.70 in revenue.
A6: Bethel /Stanley Strader | H6: =(C6-F6)/C6 -> #DIV/0! | J6: =C6/F6 -> #DIV/0! | K6: =D6/F6 -> #DIV/0!
A7: Gym | C7: 70 | D7: =C7+20 -> 90 | E7: $6.39/Utilities and $16.20/hr Staff FA | F7: 22.59 | H7: =(C7-F7)/C7 -> 0.67728571 | I7: =(D7-F7)/D7 -> 0.749 | J7: =C7/F7 -> 3.0987162 | K7: =D7/F7 -> 3.9840637
A8: Community Room | C8: 40 | D8: =C8+20 -> 60 | E8: $2.74/Utilities and $16.20.hr Staff FA | F8: 18.94 | H8: =(C8-F8)/C8 -> 0.5265 | I8: =(D8-F8)/D8 -> 0.68433333 | J8: =C8/F8 -> 2.1119324 | K8: =D8/F8 -> 3.1678986
A9: Community Room - half | C9: 20 | D9: =C9+20 -> 40 | E9: $1.37/Utilities and $16.20 hr Staff FA | F9: 17.57 | H9: =(C9-F9)/C9 -> 0.1215 | I9: =(D9-F9)/D9 -> 0.56075 | J9: =C9/F9 -> 1.1383039 | K9: =D9/F9 -> 2.2766079
A10: Kitchen | C10: 10 | D10: =C10+20 -> 30 | E10: $16.20/hr FA/ No Utility Data | F10: 16.2 | H10: =(C10-F10)/C10 -> -0.62 | I10: =(D10-F10)/D10 -> 0.46 | J10: =C10/F10 -> 0.61728395 | K10: =D10/F10 -> 1.8518519
A11: Broad Ripple | H11: =(C11-F11)/C11 -> #DIV/0! | J11: =C11/F11 -> #DIV/0! | K11: =D11/F11 -> #DIV/0!
A12: Gym | C12: 70 | D12: =C12+20 -> 90 | E12: $16.20 hr staff/No Utility Data FA | F12: 16.2 | H12: =(C12-F12)/C12 -> 0.76857143 | I12: =(D12-F12)/D12 -> 0.82 | J12: =C12/F12 -> 4.3209877 | K12: =D12/F12 -> 5.5555556
A13: Kitchen | C13: 25 | D13: =C13+20 -> 45 | E13: $16.20 hr staff/No Utility Data FA | F13: 16.2 | H13: =(C13-F13)/C13 -> 0.352 | I13: =(D13-F13)/D13 -> 0.64 | J13: =C13/F13 -> 1.5432099 | K13: =D13/F13 -> 2.7777778
A14: Multi purpose Room | C14: 80 | D14: =C14+20 -> 100 | E14: $1.41/Utilities and $16.20/hr Staff FA | F14: 17.61 | H14: =(C14-F14)/C14 -> 0.779875 | I14: =(D14-F14)/D14 -> 0.8239 | J14: =C14/F14 -> 4.5428734 | K14: =D14/F14 -> 5.6785917
A15: Half Multi purpose Room | C15: 45 | D15: =C15+20 -> 65 | E15: No Utility Data | F15: 16.2 | H15: =(C15-F15)/C15 -> 0.64 | I15: =(D15-F15)/D15 -> 0.75076923 | J15: =C15/F15 -> 2.7777778 | K15: =D15/F15 -> 4.0123457
A16: Group Exercise Room | C16: 45 | D16: =C16+20 -> 65 | E16: No Utility Data | F16: 16.2 | H16: =(C16-F16)/C16 -> 0.64 | I16: =(D16-F16)/D16 -> 0.75076923 | J16: =C16/F16 -> 2.7777778 | K16: =D16/F16 -> 4.0123457
A17: Birthday Party Room | C17: 25 | D17: =C17+20 -> 45 | E17: No Utility Data | F17: 16.2 | H17: =(C17-F17)/C17 -> 0.352 | I17: =(D17-F17)/D17 -> 0.64 | J17: =C17/F17 -> 1.5432099 | K17: =D17/F17 -> 2.7777778
A18: Conference Room | C18: 20 | D18: =C18+20 -> 40 | E18: No Utility Data | F18: 16.2 | H18: =(C18-F18)/C18 -> 0.19 | I18: =(D18-F18)/D18 -> 0.595 | J18: =C18/F18 -> 1.2345679 | K18: =D18/F18 -> 2.4691358
A19: Brookside | H19: =(C19-F19)/C19 -> #DIV/0! | J19: =C19/F19 -> #DIV/0! | K19: =D19/F19 -> #DIV/0!
A20: Gym | C20: 60 | D20: =C20+20 -> 80 | E20: $2.09/Utilities and $16.20/hr Staff FA | F20: 18.29 | H20: =(C20-F20)/C20 -> 0.69516667 | I20: =(D20-F20)/D20 -> 0.771375 | J20: =C20/F20 -> 3.2804811 | K20: =D20/F20 -> 4.3739748
A21: Auditorium Mon-Thurs (2 hr min) includes Kitchen | C21: 55 | D21: =C21+20 -> 75 | E21: $7.85/Utilities and $16.20.hr Staff FA | F21: 24.05 | H21: =(C21-F21)/C21 -> 0.56272727 | I21: =(D21-F21)/D21 -> 0.67933333 | J21: =C21/F21 -> 2.2869023 | K21: =D21/F21 -> 3.1185031
A22: Auditorium Fri, Sat, Sun (2 hr min) includes kitchen | C22: 105 | D22: =C22+20 -> 125 | E22: $7.85/Utilities and $16.20/hr Staff FA | F22: 24.05 | H22: =(C22-F22)/C22 -> 0.77095238 | I22: =(D22-F22)/D22 -> 0.8076 | J22: =C22/F22 -> 4.3659044 | K22: =D22/F22 -> 5.1975052
A23: Auditorium Small Group of 30 or less (2 hr min) includes kitchen | C23: 55 | D23: =C23+20 -> 75 | E23: $7.85/Utilities and $16.20/hr Staff FA | F23: 24.05 | H23: =(C23-F23)/C23 -> 0.56272727 | I23: =(D23-F23)/D23 -> 0.67933333 | J23: =C23/F23 -> 2.2869023 | K23: =D23/F23 -> 3.1185031
A24: Arts and Crafts Room - Balcony | C24: 25 | D24: =C24+20 -> 45 | E24: No Utility Data | F24: 16.2 | H24: =(C24-F24)/C24 -> 0.352 | I24: =(D24-F24)/D24 -> 0.64 | J24: =C24/F24 -> 1.5432099 | K24: =D24/F24 -> 2.7777778
A25: Office Space Balcony | C25: $20/day | D25: $40/day | E25: No Utility Data | F25: 16.2 | H25: =(C25-F25)/C25 -> #VALUE! | J25: =C25/F25 -> #VALUE! | K25: =D25/F25 -> #VALUE!
A26: Conference Room -Balcony | C26: 30 | D26: =C26+20 -> 50 | E26: $0.52/Utilites and $16.20/hr Staff FA | F26: 16.72 | H26: =(C26-F26)/C26 -> 0.44266667 | I26: =(D26-F26)/D26 -> 0.6656 | J26: =C26/F26 -> 1.7942584 | K26: =D26/F26 -> 2.9904306
A27: Meeting Room - Basement | C27: 20 | D27: =C27+20 -> 40 | E27: No Utility Data | F27: 16.2 | H27: =(C27-F27)/C27 -> 0.19 | I27: =(D27-F27)/D27 -> 0.595 | J27: =C27/F27 -> 1.2345679 | K27: =D27/F27 -> 2.4691358
A28: Kitchen | C28: 15 | D28: =C28+20 -> 35 | E28: No Utility Data | F28: 16.2 | H28: =(C28-F28)/C28 -> -0.08 | I28: =(D28-F28)/D28 -> 0.53714286 | J28: =C28/F28 -> 0.92592593 | K28: =D28/F28 -> 2.1604938
A29: Christian | H29: =(C29-F29)/C29 -> #DIV/0! | J29: =C29/F29 -> #DIV/0! | K29: =D29/F29 -> #DIV/0!
A30: Gym -large | C30: 70 | D30: =C30+20 -> 90 | E30: $3.40/Utilities and $16.20/hr Staff FA | F30: 19.6 | H30: =(C30-F30)/C30 -> 0.72 | I30: =(D30-F30)/D30 -> 0.78222222 | J30: =C30/F30 -> 3.5714286 | K30: =D30/F30 -> 4.5918367
A31: Gym-1/2 court | C31: 40 | D31: =C31+20 -> 60 | E31: $3.40/Utilities and $16.20/hr Staff FA | F31: 19.6 | H31: =(C31-F31)/C31 -> 0.51 | I31: =(D31-F31)/D31 -> 0.67333333 | J31: =C31/F31 -> 2.0408163 | K31: =D31/F31 -> 3.0612245
A32: Multi-purpose room | C32: 45 | D32: =C32+20 -> 65 | E32: $2.27/Utilities and $16.20/hr Staff FA | F32: 18.47 | H32: =(C32-F32)/C32 -> 0.58955556 | I32: =(D32-F32)/D32 -> 0.71584615 | J32: =C32/F32 -> 2.4363833 | K32: =D32/F32 -> 3.5192204
A33: Kitchen | C33: 20 | D33: =C33+20 -> 40 | H33: =(C33-F33)/C33 -> 1 | I33: =(D33-F33)/D33 -> 1 | J33: =C33/F33 -> #DIV/0! | K33: =D33/F33 -> #DIV/0!
A34: Conference room | C34: 40 | D34: =C34+20 -> 60 | E34: $1.70/Utilities and $16.20/hr Staff FA | F34: 17.9 | H34: =(C34-F34)/C34 -> 0.5525 | I34: =(D34-F34)/D34 -> 0.70166667 | J34: =C34/F34 -> 2.2346369 | K34: =D34/F34 -> 3.3519553
A35: Activity Room (old fitness room, small multipurpose room) | C35: 25 | D35: =C35+20 -> 45 | E35: $2.27/Utilities and $16.20/hr Staff FA | F35: 18.47 | H35: =(C35-F35)/C35 -> 0.2612 | I35: =(D35-F35)/D35 -> 0.58955556 | J35: =C35/F35 -> 1.3535463 | K35: =D35/F35 -> 2.4363833
A36: Learning Lab | C36: 25 | D36: =C36+20 -> 45 | E36: $1.13/Utilites and $16.20/hr Staff FA | F36: 17.33 | H36: =(C36-F36)/C36 -> 0.3068 | I36: =(D36-F36)/D36 -> 0.61488889 | J36: =C36/F36 -> 1.4425851 | K36: =D36/F36 -> 2.5966532
A37: Game Room | C37: 35 | D37: =C37+20 -> 55 | E37: $1.13/Utilites and $16.20/hr Staff FA | F37: 17.33 | H37: =(C37-F37)/C37 -> 0.50485714 | I37: =(D37-F37)/D37 -> 0.68490909 | J37: =C37/F37 -> 2.0196192 | K37: =D37/F37 -> 3.1736872
A38: Douglass | H38: =(C38-F38)/C38 -> #DIV/0! | J38: =C38/F38 -> #DIV/0! | K38: =D38/F38 -> #DIV/0!
A39: Gym | C39: 70 | D39: =C39+20 -> 90 | E39: $3.24/Utlitlies and $16.20/hr Staff FA | F39: 19.44 | H39: =(C39-F39)/C39 -> 0.72228571 | I39: =(D39-F39)/D39 -> 0.784 | J39: =C39/F39 -> 3.600823 | K39: =D39/F39 -> 4.6296296
A40: Large Multi purpose Room - full | C40: 150 | D40: =C40+20 -> 170 | F40: 16.2 | H40: =(C40-F40)/C40 -> 0.892 | I40: =(D40-F40)/D40 -> 0.90470588 | J40: =C40/F40 -> 9.2592593 | K40: =D40/F40 -> 10.493827
...

Sheet regression output1
A1: SUMMARY OUTPUT
A3: Regression Statistics
A4: Multiple R | B4: 0.108638
A5: R Square | B5: 0.011802
A6: Adjusted R Square | B6: 0.009461
A7: Standard Error | B7: 2.196931 | H7: we can conlcude that based off all the services
A8: Observations | B8: 424 | H8: indy parks has a pretty inelastic demand
H9: so the desicon of rasing fees is completly justified
A10: ANOVA
B11: df | C11: SS | D11: MS | E11: F | F11: Significance F
A12: Regression | B12: 1 | C12: 24.32569 | D12: 24.32569 | E12: 5.040023 | F12: 0.025285
A13: Residual | B13: 422 | C13: 2036.785 | D13: 4.826505
A14: Total | B14: 423 | C14: 2061.111
B16: Coefficients | C16: Standard Error | D16: t Stat | E16: P-value | F16: Lower 95% | G16: Upper 95% | H16: Lower 95.0% | I16: Upper 95.0%
A17: Intercept | B17: 4.843364 | C17: 0.164031 | D17: 29.52715 | E17: 1e-104 | F17: 4.520945 | G17: 5.165783 | H17: 4.520945 | I17: 5.165783
A18: ln_Price | B18: -0.16091 | C18: 0.071675 | D18: -2.245 | E18: 0.025285 | F18: -0.30179 | G18: -0.02003 | H18: -0.30179 | I18: -0.02003
A23: Regression Statistics | D23: This regression is based off a set of dummy variables where
A24: Multiple R | B24: 0.228122 | D24: log linear of quantity sold is y and aquatic centers is x
A25: R Square | B25: 0.05204 | D25: shows that on average acuatics generate | H25: exp(1.6)= 5 | I25: times
A26: Adjusted R Square | B26: 0.049793 | D26: more participation compared to other services
A27: Standard Error | B27: 2.151738 | D27: (Recomend reconsidering price increase in aquaitc centers)
A28: Observations | B28: 424 | D28: Because they have a huge inpact on overall revenue
A30: ANOVA
B31: df | C31: SS | D31: MS | E31: F | F31: Significance F
A32: Regression | B32: 1 | C32: 107.2598 | D32: 107.2598 | E32: 23.16637 | F32: 2.07e-06
A33: Residual | B33: 422 | C33: 1953.851 | D33: 4.629978
A34: Total | B34: 423 | C34: 2061.111
B36: Coefficients | C36: Standard Error | D36: t Stat | E36: P-value | F36: Lower 95% | G36: Upper 95% | H36: Lower 95.0% | I36: Upper 95.0%
A37: Intercept | B37: 4.388202 | C37: 0.110673 | D37: 39.64998 | E37: 2.2e-144 | F37: 4.170662 | G37: 4.605742 | H37: 4.170662 | I37: 4.605742
A38: Fac_Aquatics | B38: 1.617248 | C38: 0.336006 | D38: 4.813145 | E38: 2.07e-06 | F38: 0.956793 | G38: 2.277702 | H38: 0.956793 | I38: 2.277702
A42: SUMMARY OUTPUT
A44: Regression Statistics | D44: We can conclude open gyms have lower participation
A45: Multiple R | B45: 0.402125 | D45: compared to other forms of services
A46: R Square | B46: 0.161704 | D46: Price Decerease?
A47: Adjusted R Square | B47: 0.149642
A48: Standard Error | B48: 0.440765
A49: Observations | B49: 424
A51: ANOVA
B52: df | C52: SS | D52: MS | E52: F | F52: Significance F
A53: Regression | B53: 6 | C53: 15.62696 | D53: 2.604493 | E53: 13.4063 | F53: 6.47e-14
...

Sheet regression data1
A1: Type | B1: Product | C1: Price | D1: Quantity | E1: Revenue | F1: Category | G1: Facility | H1: ln_Price | I1: ln_Quantity | J1: Type_POS | K1: Type_Pass | L1: Cat_Camp | M1: Cat_Merchandise | N1: Cat_Pass | O1: Fac_Arts center | P1: Fac_Broad Ripple | Q1: Fac_Broad Ripple Camps 2023 | R1: Fac_Brookside | S1: Fac_Brookside Park Camps 2023 | T1: Fac_Christian | U1: Fac_City Wide | V1: Fac_Concessions | W1: Fac_Conservatory | X1: Fac_Dog Park | Y1: Fac_Eagle Creek | Z1: Fac_Ellenberger Park | AA1: Fac_Ellenberger Park Camps 2023 | AB1: Fac_Fee - Youth Open Gym | AC1: Fac_Frederick Douglass | AD1: Fac_Frederick Douglass Camps 2023 | AE1: Fac_Garfield BFC | AF1: Fac_Garfield BFC Camps 2023 | AG1: Fac_Hockey Equipment | AH1: Fac_Krannert | AI1: Fac_Krannert at Bel Aire Camp 2023 | AJ1: Fac_Mini Mart | AK1: Fac_Mooring | AL1: Fac_Open Gym | AM1: Fac_Playground | AN1: Fac_Pool Entry | AO1: Fac_Program | AP1: Fac_Rental | AQ1: Fac_Rhodius | AR1: Fac_Riverside | AS1: Fac_Riverside Camps 2023 | AT1: Fac_Riverside Park | AU1: Fac_Sensory | AV1: Fac_Weight Room | AW1: Fac_Windsor | AX1: Fac_Windsor Camps 2023 | AY1: Fac_Windsor Village
A2: Camp | B2: Day Camp 2023 | 6-7 year old | Broad Ripple Camps 2023 | C2: 120 | D2: 69 | E2: 21747 | F2: Camp | G2: Broad Ripple Camps 2023 | H2: 4.787492 | I2: 4.234107 | J2: 0 | K2: 0 | L2: 1 | M2: 0 | N2: 0 | O2: 0 | P2: 0 | Q2: 1 | R2: 0 | S2: 0 | T2: 0 | U2: 0 | V2: 0 | W2: 0 | X2: 0 | Y2: 0 | Z2: 0 | AA2: 0 | AB2: 0 | AC2: 0 | AD2: 0 | AE2: 0 | AF2: 0 | AG2: 0 | AH2: 0 | AI2: 0 | AJ2: 0 | AK2: 0 | AL2: 0 | AM2: 0 | AN2: 0 | AO2: 0 | AP2: 0 | AQ2: 0 | AR2: 0 | AS2: 0 | AT2: 0 | AU2: 0 | AV2: 0 | AW2: 0 | AX2: 0 | AY2: 0
A3: Camp | B3: Day Camp 2023 | 6-8 yr old | Garfield BFC Camps 2023 | C3: 95 | D3: 48 | E3: 16071.72 | F3: Camp | G3: Garfield BFC Camps 2023 | H3: 4.553877 | I3: 3.871201 | J3: 0 | K3: 0 | L3: 1 | M3: 0 | N3: 0 | O3: 0 | P3: 0 | Q3: 0 | R3: 0 | S3: 0 | T3: 0 | U3: 0 | V3: 0 | W3: 0 | X3: 0 | Y3: 0 | Z3: 0 | AA3: 0 | AB3: 0 | AC3: 0 | AD3: 0 | AE3: 0 | AF3: 1 | AG3: 0 | AH3: 0 | AI3: 0 | AJ3: 0 | AK3: 0 | AL3: 0 | AM3: 0 | AN3: 0 | AO3: 0 | AP3: 0 | AQ3: 0 | AR3: 0 | AS3: 0 | AT3: 0 | AU3: 0 | AV3: 0 | AW3: 0 | AX3: 0 | AY3: 0
A4: Camp | B4: Day Camp 2023 | 6-8 yr old | Krannert at Bel Aire Camp 2023 | C4: 95 | D4: 25 | E4: 8020 | F4: Camp | G4: Krannert at Bel Aire Camp 2023 | H4: 4.553877 | I4: 3.218876 | J4: 0 | K4: 0 | L4: 1 | M4: 0 | N4: 0 | O4: 0 | P4: 0 | Q4: 0 | R4: 0 | S4: 0 | T4: 0 | U4: 0 | V4: 0 | W4: 0 | X4: 0 | Y4: 0 | Z4: 0 | AA4: 0 | AB4: 0 | AC4: 0 | AD4: 0 | AE4: 0 | AF4: 0 | AG4: 0 | AH4: 0 | AI4: 1 | AJ4: 0 | AK4: 0 | AL4: 0 | AM4: 0 | AN4: 0 | AO4: 0 | AP4: 0 | AQ4: 0 | AR4: 0 | AS4: 0 | AT4: 0 | AU4: 0 | AV4: 0 | AW4: 0 | AX4: 0 | AY4: 0
A5: Camp | B5: Day Camp 2023 | 8 -10 year old | Broad Ripple | C5: 120 | D5: 90 | E5: 34169.8 | F5: Camp | G5: Broad Ripple | H5: 4.787492 | I5: 4.49981 | J5: 0 | K5: 0 | L5: 1 | M5: 0 | N5: 0 | O5: 0 | P5: 1 | Q5: 0 | R5: 0 | S5: 0 | T5: 0 | U5: 0 | V5: 0 | W5: 0 | X5: 0 | Y5: 0 | Z5: 0 | AA5: 0 | AB5: 0 | AC5: 0 | AD5: 0 | AE5: 0 | AF5: 0 | AG5: 0 | AH5: 0 | AI5: 0 | AJ5: 0 | AK5: 0 | AL5: 0 | AM5: 0 | AN5: 0 | AO5: 0 | AP5: 0 | AQ5: 0 | AR5: 0 | AS5: 0 | AT5: 0 | AU5: 0 | AV5: 0 | AW5: 0 | AX5: 0 | AY5: 0
A6: Camp | B6: Day Camp 2023 | 9-12 yr old | Garfield BFC Camps 2023 | C6: 95 | D6: 40 | E6: 15544 | F6: Camp | G6: Garfield BFC Camps 2023 | H6: 4.553877 | I6: 3.688879 | J6: 0 | K6: 0 | L6: 1 | M6: 0 | N6: 0 | O6: 0 | P6: 0 | Q6: 0 | R6: 0 | S6: 0 | T6: 0 | U6: 0 | V6: 0 | W6: 0 | X6: 0 | Y6: 0 | Z6: 0 | AA6: 0 | AB6: 0 | AC6: 0 | AD6: 0 | AE6: 0 | AF6: 1 | AG6: 0 | AH6: 0 | AI6: 0 | AJ6: 0 | AK6: 0 | AL6: 0 | AM6: 0 | AN6: 0 | AO6: 0 | AP6: 0 | AQ6: 0 | AR6: 0 | AS6: 0 | AT6: 0 | AU6: 0 | AV6: 0 | AW6: 0 | AX6: 0 | AY6: 0
A7: Camp | B7: Day Camp 2023 | 9-13 yr old | Krannert at Bel Aire Camp 2023 | C7: 95 | D7: 16 | E7: 7095 | F7: Camp | G7: Krannert at Bel Aire Camp 2023 | H7: 4.553877 | I7: 2.772589 | J7: 0 | K7: 0 | L7: 1 | M7: 0 | N7: 0 | O7: 0 | P7: 0 | Q7: 0 | R7: 0 | S7: 0 | T7: 0 | U7: 0 | V7: 0 | W7: 0 | X7: 0 | Y7: 0 | Z7: 0 | AA7: 0 | AB7: 0 | AC7: 0 | AD7: 0 | AE7: 0 | AF7: 0 | AG7: 0 | AH7: 0 | AI7: 1 | AJ7: 0 | AK7: 0 | AL7: 0 | AM7: 0 | AN7: 0 | AO7: 0 | AP7: 0 | AQ7: 0 | AR7: 0 | AS7: 0 | AT7: 0 | AU7: 0 | AV7: 0 | AW7: 0 | AX7: 0 | AY7: 0
A8: Camp | B8: Day Camp 2023 | Brookside Park Camps 2023 | C8: 35 | D8: 36 | E8: 6938 | F8: Camp | G8: Brookside Park Camps 2023 | H8: 3.555348 | I8: 3.583519 | J8: 0 | K8: 0 | L8: 1 | M8: 0 | N8: 0 | O8: 0 | P8: 0 | Q8: 0 | R8: 0 | S8: 1 | T8: 0 | U8: 0 | V8: 0 | W8: 0 | X8: 0 | Y8: 0 | Z8: 0 | AA8: 0 | AB8: 0 | AC8: 0 | AD8: 0 | AE8: 0 | AF8: 0 | AG8: 0 | AH8: 0 | AI8: 0 | AJ8: 0 | AK8: 0 | AL8: 0 | AM8: 0 | AN8: 0 | AO8: 0 | AP8: 0 | AQ8: 0 | AR8: 0 | AS8: 0 | AT8: 0 | AU8: 0 | AV8: 0 | AW8: 0 | AX8: 0 | AY8: 0
A9: Camp | B9: Day Camp 2023 | Camp Gather | Rhodius | C9: 120 | D9: 27 | E9: 11229.45 | F9: Camp | G9: Rhodius | H9: 4.787492 | I9: 3.295837 | J9: 0 | K9: 0 | L9: 1 | M9: 0 | N9: 0 | O9: 0 | P9: 0 | Q9: 0 | R9: 0 | S9: 0 | T9: 0 | U9: 0 | V9: 0 | W9: 0 | X9: 0 | Y9: 0 | Z9: 0 | AA9: 0 | AB9: 0 | AC9: 0 | AD9: 0 | AE9: 0 | AF9: 0 | AG9: 0 | AH9: 0 | AI9: 0 | AJ9: 0 | AK9: 0 | AL9: 0 | AM9: 0 | AN9: 0 | AO9: 0 | AP9: 0 | AQ9: 1 | AR9: 0 | AS9: 0 | AT9: 0 | AU9: 0 | AV9: 0 | AW9: 0 | AX9: 0 | AY9: 0
A10: Camp | B10: Day Camp 2023 | Camp Gather on the Move | Rhodius | C10: 120 | D10: 20 | E10: 9555 | F10: Camp | G10: Rhodius | H10: 4.787492 | I10: 2.995732 | J10: 0 | K10: 0 | L10: 1 | M10: 0 | N10: 0 | O10: 0 | P10: 0 | Q10: 0 | R10: 0 | S10: 0 | T10: 0 | U10: 0 | V10: 0 | W10: 0 | X10: 0 | Y10: 0 | Z10: 0 | AA10: 0 | AB10: 0 | AC10: 0 | AD10: 0 | AE10: 0 | AF10: 0 | AG10: 0 | AH10: 0 | AI10: 0 | AJ10: 0 | AK10: 0 | AL10: 0 | AM10: 0 | AN10: 0 | AO10: 0 | AP10: 0 | AQ10: 1 | AR10: 0 | AS10: 0 | AT10: 0 | AU10: 0 | AV10: 0 | AW10: 0 | AX10: 0 | AY10: 0
A11: Camp | B11: Day Camp 2023 | Ellenberger Park Camps 2023 | C11: 105 | D11: 44 | E11: 17092.5 | F11: Camp | G11: Ellenberger Park Camps 2023 | H11: 4.65396 | I11: 3.78419 | J11: 0 | K11: 0 | L11: 1 | M11: 0 | N11: 0 | O11: 0 | P11: 0 | Q11: 0 | R11: 0 | S11: 0 | T11: 0 | U11: 0 | V11: 0 | W11: 0 | X11: 0 | Y11: 0 | Z11: 0 | AA11: 1 | AB11: 0 | AC11: 0 | AD11: 0 | AE11: 0 | AF11: 0 | AG11: 0 | AH11: 0 | AI11: 0 | AJ11: 0 | AK11: 0 | AL11: 0 | AM11: 0 | AN11: 0 | AO11: 0 | AP11: 0 | AQ11: 0 | AR11: 0 | AS11: 0 | AT11: 0 | AU11: 0 | AV11: 0 | AW11: 0 | AX11: 0 | AY11: 0
A12: Camp | B12: Day Camp 2023 | Frederick Douglass Camps 2023 | C12: 35 | D12: 26 | E12: 3933.5 | F12: Camp | G12: Frederick Douglass Camps 2023 | H12: 3.555348 | I12: 3.258097 | J12: 0 | K12: 0 | L12: 1 | M12: 0 | N12: 0 | O12: 0 | P12: 0 | Q12: 0 | R12: 0 | S12: 0 | T12: 0 | U12: 0 | V12: 0 | W12: 0 | X12: 0 | Y12: 0 | Z12: 0 | AA12: 0 | AB12: 0 | AC12: 0 | AD12: 1 | AE12: 0 | AF12: 0 | AG12: 0 | AH12: 0 | AI12: 0 | AJ12: 0 | AK12: 0 | AL12: 0 | AM12: 0 | AN12: 0 | AO12: 0 | AP12: 0 | AQ12: 0 | AR12: 0 | AS12: 0 | AT12: 0 | AU12: 0 | AV12: 0 | AW12: 0 | AX12: 0 | AY12: 0
A13: Camp | B13: Day Camp 2023 | Riverside Camps 2023 | C13: 65 | D13: 37 | E13: 10559.75 | F13: Camp | G13: Riverside Camps 2023 | H13: 4.174387 | I13: 3.610918 | J13: 0 | K13: 0 | L13: 1 | M13: 0 | N13: 0 | O13: 0 | P13: 0 | Q13: 0 | R13: 0 | S13: 0 | T13: 0 | U13: 0 | V13: 0 | W13: 0 | X13: 0 | Y13: 0 | Z13: 0 | AA13: 0 | AB13: 0 | AC13: 0 | AD13: 0 | AE13: 0 | AF13: 0 | AG13: 0 | AH13: 0 | AI13: 0 | AJ13: 0 | AK13: 0 | AL13: 0 | AM13: 0 | AN13: 0 | AO13: 0 | AP13: 0 | AQ13: 0 | AR13: 0 | AS13: 1 | AT13: 0 | AU13: 0 | AV13: 0 | AW13: 0 | AX13: 0 | AY13: 0
... A49: Camp | B49: Day Camp 2025 | Windsor Village | C49: 45 | D49: 54 | E49: 12513 | F49: Camp | G49: Windsor Village | H49: 3.806662 | I49: 3.988984 | J49: 0 | K49: 0 | L49: 1 | M49: 0 | N49: 0 | O49: 0 | P49: 0 | Q49: 0 | R49: 0 | S49: 0 | T49: 0 | U49: 0 | V49: 0 | W49: 0 | X49: 0 | Y49: 0 | Z49: 0 | AA49: 0 | AB49: 0 | AC49: 0 | AD49: 0 | AE49: 0 | AF49: 0 | AG49: 0 | AH49: 0 | AI49: 0 | AJ49: 0 | AK49: 0 | AL49: 0 | AM49: 0 | AN49: 0 | AO49: 0 | AP49: 0 | AQ49: 0 | AR49: 0 | AS49: 0 | AT49: 0 | AU49: 0 | AV49: 0 | AW49: 0 | AX49: 0 | AY49: 1
A50: Pass | B50: Eagle Creek Single Day Vehicle Pass | C50: 6 | D50: 1 | E50: 6 | F50: Pass | H50: 1.791759 | I50: 0 | J50: 0 | K50: 1 | L50: 0 | M50: 0 | N50: 1 | O50: 0 | P50: 0 | Q50: 0 | R50: 0 | S50: 0 | T50: 0 | U50: 0 | V50: 0 | W50: 0 | X50: 0 | Y50: 0 | Z50: 0 | AA50: 0 | AB50: 0 | AC50: 0 | AD50: 0 | AE50: 0 | AF50: 0 | AG50: 0 | AH50: 0 | AI50: 0 | AJ50: 0 | AK50: 0 | AL50: 0 | AM50: 0 | AN50: 0 | AO50: 0 | AP50: 0 | AQ50: 0 | AR50: 0 | AS50: 0 | AT50: 0 | AU50: 0 | AV50: 0 | AW50: 0 | AX50: 0 | AY50: 0
A51: Pass | B51: 2024 Eagle Creek Senior Veteran Pass | C51: 10 | D51: 494 | E51: 990 | F51: Pass | H51: 2.302585 | I51: 6.202536 | J51: 0 | K51: 1 | L51: 0 | M51: 0 | N51: 1 | O51: 0 | P51: 0 | Q51: 0 | R51: 0 | S51: 0 | T51: 0 | U51: 0 | V51: 0 | W51: 0 | X51: 0 | Y51: 0 | Z51: 0 | AA51: 0 | AB51: 0 | AC51: 0 | AD51: 0 | AE51: 0 | AF51: 0 | AG51: 0 | AH51: 0 | AI51: 0 | AJ51: 0 | AK51: 0 | AL51: 0 | AM51: 0 | AN51: 0 | AO51: 0 | AP51: 0 | AQ51: 0 | AR51: 0 | AS51: 0 | AT51: 0 | AU51: 0 | AV51: 0 | AW51: 0 | AX51: 0 | AY51: 0
A52: Pass | B52: Garfield Park Weight Room | C52: 10 | D52: 1 | E52: 10 | F52: Pass | H52: 2.302585 | I52: 0 | J52: 0 | K52: 1 | L52: 0 | M52: 0 | N52: 1 | O52: 0 | P52: 0 | Q52: 0 | R52: 0 | S52: 0 | T52: 0 | U52: 0 | V52: 0 | W52: 0 | X52: 0 | Y52: 0 | Z52: 0 | AA52: 0 | AB52: 0 | AC52: 0 | AD52: 0 | AE52: 0 | AF52: 0 | AG52: 0 | AH52: 0 | AI52: 0 | AJ52: 0 | AK52: 0 | AL52: 0 | AM52: 0 | AN52: 0 | AO52: 0 | AP52: 0 | AQ52: 0 | AR52: 0 | AS52: 0 | AT52: 0 | AU52: 0 | AV52: 0 | AW52: 0 | AX52: 0 | AY52: 0
A53: Pass | B53: Indy Parks Weight Room Pass | C53: 10 | D53: 266 | E53: 3840 | F53: Pass | H53: 2.302585 | I53: 5.583496 | J53: 0 | K53: 1 | L53: 0 | M53: 0 | N53: 1 | O53: 0 | P53: 0 | Q53: 0 | R53: 0 | S53: 0 | T53: 0 | U53: 0 | V53: 0 | W53: 0 | X53: 0 | Y53: 0 | Z53: 0 | AA53: 0 | AB53: 0 | AC53: 0 | AD53: 0 | AE53: 0 | AF53: 0 | AG53: 0 | AH53: 0 | AI53: 0 | AJ53: 0 | AK53: 0 | AL53: 0 | AM53: 0 | AN53: 0 | AO53: 0 | AP53: 0 | AQ53: 0 | AR53: 0 | AS53: 0 | AT53: 0 | AU53: 0 | AV53: 0 | AW53: 0 | AX53: 0 | AY53: 0
A54: Pass | B54: Krannert Park Weight Room | C54: 10 | D54: 917 | E54: 12410 | F54: Pass | H54: 2.302585 | I54: 6.821107 | J54: 0 | K54: 1 | L54: 0 | M54: 0 | N54: 1 | O54: 0 | P54: 0 | Q54: 0 | R54: 0 | S54: 0 | T54: 0 | U54: 0 | V54: 0 | W54: 0 | X54: 0 | Y54: 0 | Z54: 0 | AA54: 0 | AB54: 0 | AC54: 0 | AD54: 0 | AE54: 0 | AF54: 0 | AG54: 0 | AH54: 0 | AI54: 0 | AJ54: 0 | AK54: 0 | AL54: 0 | AM54: 0 | AN54: 0 | AO54: 0 | AP54: 0 | AQ54: 0 | AR54: 0 | AS54: 0 | AT54: 0 | AU54: 0 | AV54: 0 | AW54: 0 | AX54: 0 | AY54: 0
A55: Pass | B55: Rhodius Park Weight Room | C55: 10 | D55: 1 | E55: 20 | F55: Pass | H55: 2.302585 | I55: 0 | J55: 0 | K55: 1 | L55: 0 | M55: 0 | N55: 1 | O55: 0 | P55: 0 | Q55: 0 | R55: 0 | S55: 0 | T55: 0 | U55: 0 | V55: 0 | W55: 0 | X55: 0 | Y55: 0 | Z55: 0 | AA55: 0 | AB55: 0 | AC55: 0 | AD55: 0 | AE55: 0 | AF55: 0 | AG55: 0 | AH55: 0 | AI55: 0 | AJ55: 0 | AK55: 0 | AL55: 0 | AM55: 0 | AN55: 0 | AO55: 0 | AP55: 0 | AQ55: 0 | AR55: 0 | AS55: 0 | AT55: 0 | AU55: 0 | AV55: 0 | AW55: 0 | AX55: 0 | AY55: 0
A56: Pass | B56: Riverside Park Weight Room | C56: 10 | D56: 77 | E56: 870 | F56: Pass | H56: 2.302585 | I56: 4.343805 | J56: 0 | K56: 1 | L56: 0 | M56: 0 | N56: 1 | O56: 0 | P56: 0 | Q56: 0 | R56: 0 | S56: 0 | T56: 0 | U56: 0 | V56: 0 | W56: 0 | X56: 0 | Y56: 0 | Z56: 0 | AA56: 0 | AB56: 0 | AC56: 0 | AD56: 0 | AE56: 0 | AF56: 0 | AG56: 0 | AH56: 0 | AI56: 0 | AJ56: 0 | AK56: 0 | AL56: 0 | AM56: 0 | AN56: 0 | AO56: 0 | AP56: 0 | AQ56: 0 | AR56: 0 | AS56: 0 | AT56: 0 | AU56: 0 | AV56: 0 | AW56: 0 | AX56: 0 | AY56: 0
A57: Pass | B57: Thatcher Park Weight Room | C57: 10 | D57: 101 | E57: 1240 | F57: Pass | H57: 2.302585 | I57: 4.615121 | J57: 0 | K57: 1 | L57: 0 | M57: 0 | N57: 1 | O57: 0 | P57: 0 | Q57: 0 | R57: 0 | S57: 0 | T57: 0 | U57: 0 | V57: 0 | W57: 0 | X57: 0 | Y57: 0 | Z57: 0 | AA57: 0 | AB57: 0 | AC57: 0 | AD57: 0 | AE57: 0 | AF57: 0 | AG57: 0 | AH57: 0 | AI57: 0 | AJ57: 0 | AK57: 0 | AL57: 0 | AM57: 0 | AN57: 0 | AO57: 0 | AP57: 0 | AQ57: 0 | AR57: 0 | AS57: 0 | AT57: 0 | AU57: 0 | AV57: 0 | AW57: 0 | AX57: 0 | AY57: 0
A58: Pass | B58: Washington Park Weight Room | C58: 10 | D58: 6 | E58: 70 | F58: Pass | H58: 2.302585 | I58: 1.791759 | J58: 0 | K58: 1 | L58: 0 | M58: 0 | N58: 1 | O58: 0 | P58: 0 | Q58: 0 | R58: 0 | S58: 0 | T58: 0 | U58: 0 | V58: 0 | W58: 0 | X58: 0 | Y58: 0 | Z58: 0 | AA58: 0 | AB58: 0 | AC58: 0 | AD58: 0 | AE58: 0 | AF58: 0 | AG58: 0 | AH58: 0 | AI58: 0 | AJ58: 0 | AK58: 0 | AL58: 0 | AM58: 0 | AN58: 0 | AO58: 0 | AP58: 0 | AQ58: 0 | AR58: 0 | AS58: 0 | AT58: 0 | AU58: 0 | AV58: 0 | AW58: 0 | AX58: 0 | AY58: 0
A59: Pass | B59: Indy Parks Weight Room Pass | C59: 10 | D59: 1023 | E59: 13210 | F59: Pass | H59: 2.302585 | I59: 6.930495 | J59: 0 | K59: 1 | L59: 0 | M59: 0 | N59: 1 | O59: 0 | P59: 0 | Q59: 0 | R59: 0 | S59: 0 | T59: 0 | U59: 0 | V59: 0 | W59: 0 | X59: 0 | Y59: 0 | Z59: 0 | AA59: 0 | AB59: 0 | AC59: 0 | AD59: 0 | AE59: 0 | AF59: 0 | AG59: 0 | AH59: 0 | AI59: 0 | AJ59: 0 | AK59: 0 | AL59: 0 | AM59: 0 | AN59: 0 | AO59: 0 | AP59: 0 | AQ59: 0 | AR59: 0 | AS59: 0 | AT59: 0 | AU59: 0 | AV59: 0 | AW59: 0 | AX59: 0 | AY59: 0
A60: Pass | B60: Krannert Park Weight Room | C60: 10 | D60: 61 | E60: 730 | F60: Pass | H60: 2.302585 | I60: 4.110874 | J60: 0 | K60: 1 | L60: 0 | M60: 0 | N60: 1 | O60: 0 | P60: 0 | Q60: 0 | R60: 0 | S60: 0 | T60: 0 | U60: 0 | V60: 0 | W60: 0 | X60: 0 | Y60: 0 | Z60: 0 | AA60: 0 | AB60: 0 | AC60: 0 | AD60: 0 | AE60: 0 | AF60: 0 | AG60: 0 | AH60: 0 | AI60: 0 | AJ60: 0 | AK60: 0 | AL60: 0 | AM60: 0 | AN60: 0 | AO60: 0 | AP60: 0 | AQ60: 0 | AR60: 0 | AS60: 0 | AT60: 0 | AU60: 0 | AV60: 0 | AW60: 0 | AX60: 0 | AY60: 0
A61: Pass | B61: Riverside Park Weight Room | C61: 10 | D61: 22 | E61: 280 | F61: Pass | H61: 2.302585 | I61: 3.091042 | J61: 0 | K61: 1 | L61: 0 | M61: 0 | N61: 1 | O61: 0 | P61: 0 | Q61: 0 | R61: 0 | S61: 0 | T61: 0 | U61: 0 | V61: 0 | W61: 0 | X61: 0 | Y61: 0 | Z61: 0 | AA61: 0 | AB61: 0 | AC61: 0 | AD61: 0 | AE61: 0 | AF61: 0 | AG61: 0 | AH61: 0 | AI61: 0 | AJ61: 0 | AK61: 0 | AL61: 0 | AM61: 0 | AN61: 0 | AO61: 0 | AP61: 0 | AQ61: 0 | AR61: 0 | AS61: 0 | AT61: 0 | AU61: 0 | AV61: 0 | AW61: 0 | AX61: 0 | AY61: 0
... A112: Pass | B112: Garfield Conservatory Family Annual Pass | C112: 70 | D112: 15 | E112: 140 | F112: Pass | H112: 4.248495 | I112: 2.70805 | J112: 0 | K112: 1 | L112: 0 | M112: 0 | N112: 1 | O112: 0 | P112: 0 | Q112: 0 | R112: 0 | S112: 0 | T112: 0 | U112: 0 | V112: 0 | W112: 0 | X112: 0 | Y112: 0 | Z112: 0 | AA112: 0 | AB112: 0 | AC112: 0 | AD112: 0 | AE112: 0 | AF112: 0 | AG112: 0 | AH112: 0 | AI112: 0 | AJ112: 0 | AK112: 0 | AL112: 0 | AM112: 0 | AN112: 0 | AO112: 0 | AP112: 0 | AQ112: 0 | AR112: 0 | AS112: 0 | AT112: 0 | AU112: 0 | AV112: 0 | AW112: 0 | AX112: 0 | AY112: 0
A113: POS | B113: 13-17 Open Gym | C113: 1 | D113: 1 | E113: 1 | F113: Admission | G113: Fee - Youth Open Gym | H113: 0 | I113: 0 | J113: 1 | K113: 0 | L113: 0 | M113: 0 | N113: 0 | O113: 0 | P113: 0 | Q113: 0 | R113: 0 | S113: 0 | T113: 0 | U113: 0 | V113: 0 | W113: 0 | X113: 0 | Y113: 0 | Z113: 0 | AA113: 0 | AB113: 1 | AC113: 0 | AD113: 0 | AE113: 0 | AF113: 0 | AG113: 0 | AH113: 0 | AI113: 0 | AJ113: 0 | AK113: 0 | AL113: 0 | AM113: 0 | AN113: 0 | AO113: 0 | AP113: 0 | AQ113: 0 | AR113: 0 | AS113: 0 | AT113: 0 | AU113: 0 | AV113: 0 | AW113: 0 | AX113: 0 | AY113: 0
A114: POS | B114: Bethel - After School Tennis | C114: 1 | D114: 67 | E114: 67 | F114: Admission | G114: Open Gym | H114: 0 | I114: 4.204693 | J114: 1 | K114: 0 | L114: 0 | M114: 0 | N114: 0 | O114: 0 | P114: 0 | Q114: 0 | R114: 0 | S114: 0 | T114: 0 | U114: 0 | V114: 0 | W114: 0 | X114: 0 | Y114: 0 | Z114: 0 | AA114: 0 | AB114: 0 | AC114: 0 | AD114: 0 | AE114: 0 | AF114: 0 | AG114: 0 | AH114: 0 | AI114: 0 | AJ114: 0 | AK114: 0 | AL114: 1 | AM114: 0 | AN114: 0 | AO114: 0 | AP114: 0 | AQ114: 0 | AR114: 0 | AS114: 0 | AT114: 0 | AU114: 0 | AV114: 0 | AW114: 0 | AX114: 0 | AY114: 0
A115: POS | B115: Douglass - Airheads | C115: 0.25 | D115: 165 | E115: 41.15 | F115: Merchandise | G115: Mini Mart | H115: -1.38629 | I115: 5.105945 | J115: 1 | K115: 0 | L115: 0 | M115: 1 | N115: 0 | O115: 0 | P115: 0 | Q115: 0 | R115: 0 | S115: 0 | T115: 0 | U115: 0 | V115: 0 | W115: 0 | X115: 0 | Y115: 0 | Z115: 0 | AA115: 0 | AB115: 0 | AC115: 0 | AD115: 0 | AE115: 0 | AF115: 0 | AG115: 0 | AH115: 0 | AI115: 0 | AJ115: 1 | AK115: 0 | AL115: 0 | AM115: 0 | AN115: 0 | AO115: 0 | AP115: 0 | AQ115: 0 | AR115: 0 | AS115: 0 | AT115: 0 | AU115: 0 | AV115: 0 | AW115: 0 | AX115: 0 | AY115: 0
A116: POS | B116: Bethel - Airheads | C116: 0.5 | D116: 104 | E116: 50 | F116: Merchandise | G116: Mini Mart | H116: -0.69315 | I116: 4.644391 | J116: 1 | K116: 0 | L116: 0 | M116: 1 | N116: 0 | O116: 0 | P116: 0 | Q116: 0 | R116: 0 | S116: 0 | T116: 0 | U116: 0 | V116: 0 | W116: 0 | X116: 0 | Y116: 0 | Z116: 0 | AA116: 0 | AB116: 0 | AC116: 0 | AD116: 0 | AE116: 0 | AF116: 0 | AG116: 0 | AH116: 0 | AI116: 0 | AJ116: 1 | AK116: 0 | AL116: 0 | AM116: 0 | AN116: 0 | AO116: 0 | AP116: 0 | AQ116: 0 | AR116: 0 | AS116: 0 | AT116: 0 | AU116: 0 | AV116: 0 | AW116: 0 | AX116: 0 | AY116: 0
A117: POS | B117: Brookside - Airheads | C117: 0.5 | D117: 68 | E117: 34 | F117: Merchandise | G117: Mini Mart | H117: -0.69315 | I117: 4.219508 | J117: 1 | K117: 0 | L117: 0 | M117: 1 | N117: 0 | O117: 0 | P117: 0 | Q117: 0 | R117: 0 | S117: 0 | T117: 0 | U117: 0 | V117: 0 | W117: 0 | X117: 0 | Y117: 0 | Z117: 0 | AA117: 0 | AB117: 0 | AC117: 0 | AD117: 0 | AE117: 0 | AF117: 0 | AG117: 0 | AH117: 0 | AI117: 0 | AJ117: 1 | AK117: 0 | AL117: 0 | AM117: 0 | AN117: 0 | AO117: 0 | AP117: 0 | AQ117: 0 | AR117: 0 | AS117: 0 | AT117: 0 | AU117: 0 | AV117: 0 | AW117: 0 | AX117: 0 | AY117: 0
A118: POS | B118: Bethel - City Wide Basketball | C118: 2 | D118: 148 | E118: 296 | F118: Admission | G118: City Wide | H118: 0.693147 | I118: 4.997212 | J118: 1 | K118: 0 | L118: 0 | M118: 0 | N118: 0 | O118: 0 | P118: 0 | Q118: 0 | R118: 0 | S118: 0 | T118: 0 | U118: 1 | V118: 0 | W118: 0 | X118: 0 | Y118: 0 | Z118: 0 | AA118: 0 | AB118: 0 | AC118: 0 | AD118: 0 | AE118: 0 | AF118: 0 | AG118: 0 | AH118: 0 | AI118: 0 | AJ118: 0 | AK118: 0 | AL118: 0 | AM118: 0 | AN118: 0 | AO118: 0 | AP118: 0 | AQ118: 0 | AR118: 0 | AS118: 0 | AT118: 0 | AU118: 0 | AV118: 0 | AW118: 0 | AX118: 0 | AY118: 0
A119: POS | B119: Bethel - Citywide Ball Spectator | C119: 2 | D119: 50 | E119: 100 | F119: Admission | G119: City Wide | H119: 0.693147 | I119: 3.912023 | J119: 1 | K119: 0 | L119: 0 | M119: 0 | N119: 0 | O119: 0 | P119: 0 | Q119: 0 | R119: 0 | S119: 0 | T119: 0 | U119: 1 | V119: 0 | W119: 0 | X119: 0 | Y119: 0 | Z119: 0 | AA119: 0 | AB119: 0 | AC119: 0 | AD119: 0 | AE119: 0 | AF119: 0 | AG119: 0 | AH119: 0 | AI119: 0 | AJ119: 0 | AK119: 0 | AL119: 0 | AM119: 0 | AN119: 0 | AO119: 0 | AP119: 0 | AQ119: 0 | AR119: 0 | AS119: 0 | AT119: 0 | AU119: 0 | AV119: 0 | AW119: 0 | AX119: 0 | AY119: 0
A120: POS | B120: Bethel - Futsal | C120: 3 | D120: 15 | E120: 45 | F120: Admission | G120: Open Gym | H120: 1.098612 | I120: 2.70805 | J120: 1 | K120: 0 | L120: 0 | M120: 0 | N120: 0 | O120: 0 | P120: 0 | Q120: 0 | R120: 0 | S120: 0 | T120: 0 | U120: 0 | V120: 0 | W120: 0 | X120: 0 | Y120: 0 | Z120: 0 | AA120: 0 | AB120: 0 | AC120: 0 | AD120: 0 | AE120: 0 | AF120: 0 | AG120: 0 | AH120: 0 | AI120: 0 | AJ120: 0 | AK120: 0 | AL120: 1 | AM120: 0 | AN120: 0 | AO120: 0 | AP120: 0 | AQ120: 0 | AR120: 0 | AS120: 0 | AT120: 0 | AU120: 0 | AV120: 0 | AW120: 0 | AX120: 0 | AY120: 0
A121: POS | B121: Bethel - Open BBall - Adult | C121: 3 | D121: 87 | E121: 261 | F121: Admission | G121: Open Gym | H121: 1.098612 | I121: 4.465908 | J121: 1 | K121: 0 | L121: 0 | M121: 0 | N121: 0 | O121: 0 | P121: 0 | Q121: 0 | R121: 0 | S121: 0 | T121: 0 | U121: 0 | V121: 0 | W121: 0 | X121: 0 | Y121: 0 | Z121: 0 | AA121: 0 | AB121: 0 | AC121: 0 | AD121: 0 | AE121: 0 | AF121: 0 | AG121: 0 | AH121: 0 | AI121: 0 | AJ121: 0 | AK121: 0 | AL121: 1 | AM121: 0 | AN121: 0 | AO121: 0 | AP121: 0 | AQ121: 0 | AR121: 0 | AS121: 0 | AT121: 0 | AU121: 0 | AV121: 0 | AW121: 0 | AX121: 0 | AY121: 0
A122: POS | B122: Bethel - Senior Aerobics | C122: 1 | D122: 55 | E122: 55 | F122: Admission | G122: Open Gym | H122: 0 | I122: 4.007333 | J122: 1 | K122: 0 | L122: 0 | M122: 0 | N122: 0 | O122: 0 | P122: 0 | Q122: 0 | R122: 0 | S122: 0 | T122: 0 | U122: 0 | V122: 0 | W122: 0 | X122: 0 | Y122: 0 | Z122: 0 | AA122: 0 | AB122: 0 | AC122: 0 | AD122: 0 | AE122: 0 | AF122: 0 | AG122: 0 | AH122: 0 | AI122: 0 | AJ122: 0 | AK122: 0 | AL122: 1 | AM122: 0 | AN122: 0 | AO122: 0 | AP122: 0 | AQ122: 0 | AR122: 0 | AS122: 0 | AT122: 0 | AU122: 0 | AV122: 0 | AW122: 0 | AX122: 0 | AY122: 0
A123: POS | B123: ECB - Airheads | C123: 0.5 | D123: 162 | E123: 80.7 | F123: Merchandise | G123: Mini Mart | H123: -0.69315 | I123: 5.087596 | J123: 1 | K123: 0 | L123: 0 | M123: 1 | N123: 0 | O123: 0 | P123: 0 | Q123: 0 | R123: 0 | S123: 0 | T123: 0 | U123: 0 | V123: 0 | W123: 0 | X123: 0 | Y123: 0 | Z123: 0 | AA123: 0 | AB123: 0 | AC123: 0 | AD123: 0 | AE123: 0 | AF123: 0 | AG123: 0 | AH123: 0 | AI123: 0 | AJ123: 1 | AK123: 0 | AL123: 0 | AM123: 0 | AN123: 0 | AO123: 0 | AP123: 0 | AQ123: 0 | AR123: 0 | AS123: 0 | AT123: 0 | AU123: 0 | AV123: 0 | AW123: 0 | AX123: 0 | AY123: 0
A124: POS | B124: Bethel Aqua - Adult Admission | C124: 3 | D124: 830 | E124: 2486.4 | F124: Admission | G124: Aquatics | H124: 1.098612 | I124: 6.721426 | J124: 1 | K124: 0 | L124: 0 | M124: 0 | N124: 0 | O124: 0 | P124: 0 | Q124: 0 | R124: 0 | S124: 0 | T124: 0 | U124: 0 | V124: 0 | W124: 0 | X124: 0 | Y124: 0 | Z124: 0 | AA124: 0 | AB124: 0 | AC124: 0 | AD124: 0 | AE124: 0 | AF124: 0 | AG124: 0 | AH124: 0 | AI124: 0 | AJ124: 0 | AK124: 0 | AL124: 0 | AM124: 0 | AN124: 0 | AO124: 0 | AP124: 0 | AQ124: 0 | AR124: 0 | AS124: 0 | AT124: 0 | AU124: 0 | AV124: 0 | AW124: 0 | AX124: 0 | AY124: 0
... A425: POS | B425: Windsor - Pickleball | C425: 3 | D425: 145 | E425: 435 | F425: Admission | G425: Open Gym | H425: 1.098612 | I425: 4.976734 | J425: 1 | K425: 0 | L425: 0 | M425: 0 | N425: 0 | O425: 0 | P425: 0 | Q425: 0 | R425: 0 | S425: 0 | T425: 0 | U425: 0 | V425: 0 | W425: 0 | X425: 0 | Y425: 0 | Z425: 0 | AA425: 0 | AB425: 0 | AC425: 0 | AD425: 0 | AE425: 0 | AF425: 0 | AG425: 0 | AH425: 0 | AI425: 0 | AJ425: 0 | AK425: 0 | AL425: 1 | AM425: 0 | AN425: 0 | AO425: 0 | AP425: 0 | AQ425: 0 | AR425: 0 | AS425: 0 | AT425: 0 | AU425: 0 | AV425: 0 | AW425: 0 | AX425: 0 | AY425: 0

Sheet regression data
A1: Type | B1: Product | C1: Price | D1: Quantity | E1: Revenue | F1: Category | G1: Facility | H1: ln_Price | I1: ln_Quantity
A2: Camp | B2: Day Camp 2023 | 6-7 year old | Broad Ripple Camps 2023 | C2: 120 | D2: 69 | E2: 21747 | F2: Camp | G2: Broad Ripple Camps 2023 | H2: 4.787492 | I2: 4.234107
A3: Camp | B3: Day Camp 2023 | 6-8 yr old | Garfield BFC Camps 2023 | C3: 95 | D3: 48 | E3: 16071.72 | F3: Camp | G3: Garfield BFC Camps 2023 | H3: 4.553877 | I3: 3.871201
A4: Camp | B4: Day Camp 2023 | 6-8 yr old | Krannert at Bel Aire Camp 2023 | C4: 95 | D4: 25 | E4: 8020 | F4: Camp | G4: Krannert at Bel Aire Camp 2023 | H4: 4.553877 | I4: 3.218876
A5: Camp | B5: Day Camp 2023 | 8 -10 year old | Broad Ripple | C5: 120 | D5: 90 | E5: 34169.8 | F5: Camp | G5: Broad Ripple | H5: 4.787492 | I5: 4.49981
A6: Camp | B6: Day Camp 2023 | 9-12 yr old | Garfield BFC Camps 2023 | C6: 95 | D6: 40 | E6: 15544 | F6: Camp | G6: Garfield BFC Camps 2023 | H6: 4.553877 | I6: 3.688879
A7: Camp | B7: Day Camp 2023 | 9-13 yr old | Krannert at Bel Aire Camp 2023 | C7: 95 | D7: 16 | E7: 7095 | F7: Camp | G7: Krannert at Bel Aire Camp 2023 | H7: 4.553877 | I7: 2.772589
A8: Camp | B8: Day Camp 2023 | Brookside Park Camps 2023 | C8: 35 | D8: 36 | E8: 6938 | F8: Camp | G8: Brookside Park Camps 2023 | H8: 3.555348 | I8: 3.583519
A9: Camp | B9: Day Camp 2023 | Camp Gather | Rhodius | C9: 120 | D9: 27 | E9: 11229.45 | F9: Camp | G9: Rhodius | H9: 4.787492 | I9: 3.295837
A10: Camp | B10: Day Camp 2023 | Camp Gather on the Move | Rhodius | C10: 120 | D10: 20 | E10: 9555 | F10: Camp | G10: Rhodius | H10: 4.787492 | I10: 2.995732
A11: Camp | B11: Day Camp 2023 | Ellenberger Park Camps 2023 | C11: 105 | D11: 44 | E11: 17092.5 | F11: Camp | G11: Ellenberger Park Camps 2023 | H11: 4.65396 | I11: 3.78419
A12: Camp | B12: Day Camp 2023 | Frederick Douglass Camps 2023 | C12: 35 | D12: 26 | E12: 3933.5 | F12: Camp | G12: Frederick Douglass Camps 2023 | H12: 3.555348 | I12: 3.258097
A13: Camp | B13: Day Camp 2023 | Riverside Camps 2023 | C13: 65 | D13: 37 | E13: 10559.75 | F13: Camp | G13: Riverside Camps 2023 | H13: 4.174387 | I13: 3.610918
... A425: POS | B425: Windsor - Pickleball | C425: 3 | D425: 145 | E425: 435 | F425: Admission | G425: Open Gym | H425: 1.098612 | I425: 4.976734

Sheet Sheet1
A1: Site | B1: Programs | C1: Total_Participants | D1: Total_Revenue | E1: Revenue_per_Participant
A2: Broad Ripple | B2: 8 | C2: 498 | D2: 98282.63 | E2: 197.3547
A3: Broad Ripple Camps 2023 | B3: 1 | C3: 69 | D3: 21747 | E3: 315.1739
A4: Brookside | B4: 2 | C4: 105 | D4: 29069 | E4: 276.8476
A5: Brookside Park Camps 2023 | B5: 1 | C5: 36 | D5: 6938 | E5: 192.7222
A6: Christian | B6: 2 | C6: 84 | D6: 18036.01 | E6: 214.7144
A7: Ellenberger Park | B7: 2 | C7: 115 | D7: 33792 | E7: 293.8435
A8: Ellenberger Park Camps 2023 | B8: 1 | C8: 44 | D8: 17092.5 | E8: 388.4659
A9: Frederick Douglass | B9: 4 | C9: 139 | D9: 54402.2 | E9: 391.3827
A10: Frederick Douglass Camps 2023 | B10: 1 | C10: 26 | D10: 3933.5 | E10: 151.2885
A11: Garfield BFC | B11: 4 | C11: 175 | D11: 66686 | E11: 381.0629
A12: Garfield BFC Camps 2023 | B12: 2 | C12: 88 | D12: 31615.72 | E12: 359.2695
A13: Krannert | B13: 6 | C13: 206 | D13: 158321.9 | E13: 768.553
... A21: Windsor Village | B21: 1 | C21: 54 | D21: 12513 | E21: 231.7222

Sheet Sheet2
A1: Package Name | B1: Years | C1: Total_Sales | D1: Total_Income | E1: Fee_Revenue
A2: 2024 Black Friday Eagle Creek Non-Resident Pass | B2: 1 | C2: 216 | D2: 10750 | E2: 10750
A3: 2024 Black Friday Eagle Creek Resident Pass | B3: 1 | C3: 671 | D3: 26840 | E3: 26840
A4: 2024 Black Friday Eagle Creek Senior Pass | B4: 1 | C4: 532 | D4: 15930 | E4: 15930
A5: 2024 Eagle Creek Disabled Veteran Pass | B5: 1 | C5: 27 | D5: 20 | E5: 0
A6: 2024 Eagle Creek Foundation | B6: 1 | C6: 1439 | D6: 0 | E6: 0
A7: 2024 Eagle Creek Non-Resident Pass | B7: 1 | C7: 1369 | D7: 15150 | E7: 82080
A8: 2024 Eagle Creek Non-Resident Veteran Pass | B8: 1 | C8: 169 | D8: 195 | E8: 5070
A9: 2024 Eagle Creek Resident | B9: 1 | C9: 2756 | D9: 26675 | E9: 137600
A10: 2024 Eagle Creek Resident Veteran Pass | B10: 1 | C10: 318 | D10: 500 | E10: 7950
A11: 2024 Eagle Creek Senior Pass | B11: 1 | C11: 1532 | D11: 9560 | E11: 30540
A12: 2024 Eagle Creek Senior Veteran Pass | B12: 1 | C12: 494 | D12: 990 | E12: 4940
A13: 2025 Black Friday Eagle Creek Non-Resident Pass | B13: 1 | C13: 265 | D13: 13250 | E13: 10600
... A74: Windsor Village - Youth Open | B74: 1 | C74: 60 | D74: 0 | E74: 0

Sheet Sheet3
A1: Category | B1: Gross_Amount | C1: Net_Amount | D1: Revenue_2025 | E1: Potential_2026
A2: Admission | B2: 1424492.4 | C2: 1424353 | D2: 1422805 | E2: 1423005
A3: Merchandise | B3: 81735.25 | C3: 81735.25 | D3: 90554 | E3: 77330.75
A4: donation | B4: 1587.39 | C4: 1587.39 | D4: 0 | E4: 0

Sheet Sheet4
A1: Product_short | B1: Revenue_2025
A2: EC - Daily Admission Resident | B2: 342924
A3: EC - Daily Admission Non Resident | B3: 168056
A4: EC - 2025 Resident Pass | B4: 119000
A5: EC - 2025 Non-Resident Pass | B5: 61560
A6: EC - 2025 Senior Pass | B6: 60560
A7: Island Aqua - Yth/Sr Admission | B7: 50780
A8: Garfield Cons - General Admission | B8: 46852
A9: Island Aqua - Adult Admission | B9: 40155
A10: Sahm Aqua - Adult Admission | B10: 32780
A11: Garfield Cons - Show Individual Admissio | B11: 31644
A12: Sahm Aqua - Yth/Sr Admission | B12: 29136
A13: Perry Aqua - Yth/Sr Admission | B13: 25256
